Workbook
Name Slicer_CMP: #N/A
Name Slicer_IE_Name: #N/A
Name Slicer_IE_Name1: #N/A
Name Slicer_Mapped_Technician1: #N/A
Name Slicer_Vehcile_Number: #N/A
Name Tbl_master: #REF!
Name Timeline_Date_of_filling: #N/A

Sheet Uttarakhand dfr
A1: S.R | B1: CMP | C1: TRIM/UPPER(Clean CMP) | D1: IE Name | E1: Vehcile Number | F1: Filler Name | G1: SAP | H1: Invoice Number | I1: Date of Invoice | J1: Date of filling | K1: Invoice filling gape | L1: gap validation | M1: Fule filling DG Kwh | N1: Fuel filling DG Hrs | O1: Before filling Fuel level | P1: Filling Qty | Q1: IF (filling category) | R1: IF AND(High Haldwani flag) | S1: Nested IF (filling category) | T1: Total fuel Balance | U1: IFS (filling category) | V1: IF OR(priority cluster flag) | W1: Site Entry date in DFR | X1: Fuel Filling Timing | Y1: Month | Z1: TEXT(Filling month) | AA1: filling year | AB1: Filling day | AC1: Handover to Technician - Name | AD1: Mapped Technician | AE1: SAP LENGTH | AF1: SAP VALIDATION
A2: 1 | B2: DEHRADUN | C2: =UPPER(TRIM(Tbl_DFR[[#This Row],[CMP]])) -> DEHRADUN | D2: Vivek Kumar | E2: UK17CA5176 | F2: ASHISH | G2: I-UW-VKSN-ENB-9097 | H2: 151303 | I2: 45931 | J2: 45933 | K2: =IF(OR(Tbl_DFR[[#This Row],[Date of filling]]="WIP",Tbl_DFR[[#This Row],[Date of Invoice ]]=""),"",Tbl_DFR[[#This Row],[Date of filling]]-Tbl_DFR[[#This Row],[Date of Invoice ]]) -> 2 | L2: =IF(ISNUMBER(Tbl_DFR[[#This Row],[Invoice filling gape]]),"valid","check") -> valid | M2: 9798 | N2: 2116 | O2: 30 | P2: 60 | Q2: =IF(Tbl_DFR[[#This Row],[Filling Qty]]>=150,"high","normal") -> normal | R2: =IF(AND(Tbl_DFR[[#This Row],[CMP]]="HALDWANI",Tbl_DFR[[#This Row],[Filling Qty]]>=150),"yes","no") -> no | S2: =IF(Tbl_DFR[[#This Row],[Filling Qty]]>=150,"high",IF(Tbl_DFR[[#This Row],[Filling Qty]]>=80,"medium","low")) -> low | T2: =P2+O2 -> 90 | U2: {=_xlfn.IFS(Tbl_DFR[[#This Row],[Filling Qty]]>=150,"HIGH",Tbl_DFR[[#This Row],[Filling Qty]]>=80,"medium",TRUE,"low")} -> low | V2: =IF(OR(Tbl_DFR[[#This Row],[CMP]]="HALDWANI",Tbl_DFR[[#This Row],[CMP]]="DEHRADUN"),"YES","NO") -> YES | W2: 45931 | X2: 45931 | Y2: 45931 | Z2: =IFERROR(TEXT(Tbl_DFR[[#This Row],[Date of filling]],"mmm"),"WIP") -> Oct | AA2: =IFERROR(YEAR(Tbl_DFR[[#This Row],[Date of filling]]),"WIP") -> 2025 | AB2: =IFERROR(TEXT(Tbl_DFR[[#This Row],[Date of filling]],"ddd"),"WIP") -> Fri | AD2: =_xlfn.XLOOKUP(Tbl_DFR[[#This Row],[SAP]],Site_master[SAP ID],Site_master[ [ TECHNICIAN Name] ],"Not found") -> Ankur Khatana | AE2: =LEN(Tbl_DFR[[#This Row],[SAP]]) -> 18 | AF2: =IF(Tbl_DFR[[#This Row],[SAP LENGTH]]=18,"valid","check") -> valid
A3: 1 | B3: HALDWANI | C3: =UPPER(TRIM(C7)) -> HALDWANI | D3: Aashish Rai | E3: UK05CA2368 | F3: GANESH | G3: I-UW-BRIG-ENB-9002 | H3: TXN100125947379 | I3: 45931 | J3: 45932 | K3: =IF(OR(Tbl_DFR[[#This Row],[Date of filling]]="WIP",Tbl_DFR[[#This Row],[Date of Invoice ]]=""),"",Tbl_DFR[[#This Row],[Date of filling]]-Tbl_DFR[[#This Row],[Date of Invoice ]]) -> 1 | L3: =IF(ISNUMBER(Tbl_DFR[[#This Row],[Invoice filling gape]]),"valid","check") -> valid | M3: 2948 | N3: 547 | O3: 0 | P3: 120 | Q3: =IF(Tbl_DFR[[#This Row],[Filling Qty]]>=150,"high","normal") -> normal | R3: =IF(AND(Tbl_DFR[[#This Row],[CMP]]="HALDWANI",Tbl_DFR[[#This Row],[Filling Qty]]>=150),"yes","no") -> no | S3: =IF(Tbl_DFR[[#This Row],[Filling Qty]]>=150,"high",IF(Tbl_DFR[[#This Row],[Filling Qty]]>=80,"medium","low")) -> medium | T3: =P3+O3 -> 120 | U3: {=_xlfn.IFS(Tbl_DFR[[#This Row],[Filling Qty]]>=150,"HIGH",Tbl_DFR[[#This Row],[Filling Qty]]>=80,"medium",TRUE,"low")} -> medium | V3: =IF(OR(Tbl_DFR[[#This Row],[CMP]]="HALDWANI",Tbl_DFR[[#This Row],[CMP]]="DEHRADUN"),"YES","NO") -> YES | W3: 45932 | Y3: 45931 | Z3: =IFERROR(TEXT(Tbl_DFR[[#This Row],[Date of filling]],"mmm"),"WIP") -> Oct | AA3: =IFERROR(YEAR(Tbl_DFR[[#This Row],[Date of filling]]),"WIP") -> 2025 | AB3: =IFERROR(TEXT(Tbl_DFR[[#This Row],[Date of filling]],"ddd"),"WIP") -> Thu | AD3: =_xlfn.XLOOKUP(Tbl_DFR[[#This Row],[SAP]],Site_master[SAP ID],Site_master[ [ TECHNICIAN Name] ],"Not found") -> Kamlesh Mahra | AE3: =LEN(Tbl_DFR[[#This Row],[SAP]]) -> 18 | AF3: =IF(Tbl_DFR[[#This Row],[SAP LENGTH]]=18,"valid","check") -> valid
A4: 2 | B4: DEHRADUN | C4: =UPPER(TRIM(Tbl_DFR[[#This Row],[CMP]])) -> DEHRADUN | D4: Vivek Kumar | E4: UK17CA5176 | F4: ASHISH | G4: I-UW-VKSN-ENB-9164 | H4: 151030 | I4: 45931 | J4: 45933 | K4: =IF(OR(Tbl_DFR[[#This Row],[Date of filling]]="WIP",Tbl_DFR[[#This Row],[Date of Invoice ]]=""),"",Tbl_DFR[[#This Row],[Date of filling]]-Tbl_DFR[[#This Row],[Date of Invoice ]]) -> 2 | L4: =IF(ISNUMBER(Tbl_DFR[[#This Row],[Invoice filling gape]]),"valid","check") -> valid | M4: 11321 | N4: 2125 | O4: 15 | P4: 80 | Q4: =IF(Tbl_DFR[[#This Row],[Filling Qty]]>=150,"high","normal") -> normal | R4: =IF(AND(Tbl_DFR[[#This Row],[CMP]]="HALDWANI",Tbl_DFR[[#This Row],[Filling Qty]]>=150),"yes","no") -> no | S4: =IF(Tbl_DFR[[#This Row],[Filling Qty]]>=150,"high",IF(Tbl_DFR[[#This Row],[Filling Qty]]>=80,"medium","low")) -> medium | T4: =P4+O4 -> 95 | U4: {=_xlfn.IFS(Tbl_DFR[[#This Row],[Filling Qty]]>=150,"HIGH",Tbl_DFR[[#This Row],[Filling Qty]]>=80,"medium",TRUE,"low")} -> medium | V4: =IF(OR(Tbl_DFR[[#This Row],[CMP]]="HALDWANI",Tbl_DFR[[#This Row],[CMP]]="DEHRADUN"),"YES","NO") -> YES | W4: 45931 | X4: 45931 | Y4: 45931 | Z4: =IFERROR(TEXT(Tbl_DFR[[#This Row],[Date of filling]],"mmm"),"WIP") -> Oct | AA4: =IFERROR(YEAR(Tbl_DFR[[#This Row],[Date of filling]]),"WIP") -> 2025 | AB4: =IFERROR(TEXT(Tbl_DFR[[#This Row],[Date of filling]],"ddd"),"WIP") -> Fri | AD4: =_xlfn.XLOOKUP(Tbl_DFR[[#This Row],[SAP]],Site_master[SAP ID],Site_master[ [ TECHNICIAN Name] ],"Not found") -> Sandeep Kumar Saini | AE4: =LEN(Tbl_DFR[[#This Row],[SAP]]) -> 18 | AF4: =IF(Tbl_DFR[[#This Row],[SAP LENGTH]]=18,"valid","check") -> valid
A5: 2 | B5: HALDWANI | C5: =UPPER(TRIM(Tbl_DFR[[#This Row],[CMP]])) -> HALDWANI | D5: Aashish Rai | E5: UK05CA2368 | F5: GANESH | G5: I-UW-BRIG-ENB-9011 | H5: TXN100125947615 | I5: 45931 | J5: 45933 | K5: =IF(OR(Tbl_DFR[[#This Row],[Date of filling]]="WIP",Tbl_DFR[[#This Row],[Date of Invoice ]]=""),"",Tbl_DFR[[#This Row],[Date of filling]]-Tbl_DFR[[#This Row],[Date of Invoice ]]) -> 2 | L5: =IF(ISNUMBER(Tbl_DFR[[#This Row],[Invoice filling gape]]),"valid","check") -> valid | M5: 613 | N5: 223 | O5: 80 | P5: 60 | Q5: =IF(Tbl_DFR[[#This Row],[Filling Qty]]>=150,"high","normal") -> normal | R5: =IF(AND(Tbl_DFR[[#This Row],[CMP]]="HALDWANI",Tbl_DFR[[#This Row],[Filling Qty]]>=150),"yes","no") -> no | S5: =IF(Tbl_DFR[[#This Row],[Filling Qty]]>=150,"high",IF(Tbl_DFR[[#This Row],[Filling Qty]]>=80,"medium","low")) -> low | T5: =P5+O5 -> 140 | U5: {=_xlfn.IFS(Tbl_DFR[[#This Row],[Filling Qty]]>=150,"HIGH",Tbl_DFR[[#This Row],[Filling Qty]]>=80,"medium",TRUE,"low")} -> low | V5: =IF(OR(Tbl_DFR[[#This Row],[CMP]]="HALDWANI",Tbl_DFR[[#This Row],[CMP]]="DEHRADUN"),"YES","NO") -> YES | W5: 45933 | Y5: 45931 | Z5: =IFERROR(TEXT(Tbl_DFR[[#This Row],[Date of filling]],"mmm"),"WIP") -> Oct | AA5: =IFERROR(YEAR(Tbl_DFR[[#This Row],[Date of filling]]),"WIP") -> 2025 | AB5: =IFERROR(TEXT(Tbl_DFR[[#This Row],[Date of filling]],"ddd"),"WIP") -> Fri | AD5: =_xlfn.XLOOKUP(Tbl_DFR[[#This Row],[SAP]],Site_master[SAP ID],Site_master[ [ TECHNICIAN Name] ],"Not found") -> Kuwar Singh Mehra | AE5: =LEN(Tbl_DFR[[#This Row],[SAP]]) -> 18 | AF5: =IF(Tbl_DFR[[#This Row],[SAP LENGTH]]=18,"valid","check") -> valid
A6: 3 | B6: DEHRADUN | C6: =UPPER(TRIM(Tbl_DFR[[#This Row],[CMP]])) -> DEHRADUN | D6: Vivek Kumar | E6: UK17CA5176 | F6: ASHISH | G6: I-UW-DRDN-ENB-9009 | H6: 151303 | I6: 45931 | J6: 45933 | K6: =IF(OR(Tbl_DFR[[#This Row],[Date of filling]]="WIP",Tbl_DFR[[#This Row],[Date of Invoice ]]=""),"",Tbl_DFR[[#This Row],[Date of filling]]-Tbl_DFR[[#This Row],[Date of Invoice ]]) -> 2 | L6: =IF(ISNUMBER(Tbl_DFR[[#This Row],[Invoice filling gape]]),"valid","check") -> valid | M6: 12772 | N6: 2842 | O6: 14 | P6: 60 | Q6: =IF(Tbl_DFR[[#This Row],[Filling Qty]]>=150,"high","normal") -> normal | R6: =IF(AND(Tbl_DFR[[#This Row],[CMP]]="HALDWANI",Tbl_DFR[[#This Row],[Filling Qty]]>=150),"yes","no") -> no | S6: =IF(Tbl_DFR[[#This Row],[Filling Qty]]>=150,"high",IF(Tbl_DFR[[#This Row],[Filling Qty]]>=80,"medium","low")) -> low | T6: =P6+O6 -> 74 | U6: {=_xlfn.IFS(Tbl_DFR[[#This Row],[Filling Qty]]>=150,"HIGH",Tbl_DFR[[#This Row],[Filling Qty]]>=80,"medium",TRUE,"low")} -> low | V6: =IF(OR(Tbl_DFR[[#This Row],[CMP]]="HALDWANI",Tbl_DFR[[#This Row],[CMP]]="DEHRADUN"),"YES","NO") -> YES | W6: 45931 | X6: 45931 | Y6: 45931 | Z6: =IFERROR(TEXT(Tbl_DFR[[#This Row],[Date of filling]],"mmm"),"WIP") -> Oct | AA6: =IFERROR(YEAR(Tbl_DFR[[#This Row],[Date of filling]]),"WIP") -> 2025 | AB6: =IFERROR(TEXT(Tbl_DFR[[#This Row],[Date of filling]],"ddd"),"WIP") -> Fri | AD6: =_xlfn.XLOOKUP(Tbl_DFR[[#This Row],[SAP]],Site_master[SAP ID],Site_master[ [ TECHNICIAN Name] ],"Not found") -> Ankur Khatana | AE6: =LEN(Tbl_DFR[[#This Row],[SAP]]) -> 18 | AF6: =IF(Tbl_DFR[[#This Row],[SAP LENGTH]]=18,"valid","check") -> valid
A7: 3 | B7: HALDWANI | C7: =UPPER(TRIM(Tbl_DFR[[#This Row],[CMP]])) -> HALDWANI | D7: Aashish Rai | E7: UK05CA2368 | F7: GANESH | G7: I-UW-BRIG-ENB-9016 | H7: TXN100125951772 | I7: 45931 | J7: 45932 | K7: =IF(OR(Tbl_DFR[[#This Row],[Date of filling]]="WIP",Tbl_DFR[[#This Row],[Date of Invoice ]]=""),"",Tbl_DFR[[#This Row],[Date of filling]]-Tbl_DFR[[#This Row],[Date of Invoice ]]) -> 1 | L7: =IF(ISNUMBER(Tbl_DFR[[#This Row],[Invoice filling gape]]),"valid","check") -> valid | M7: 6772 | N7: 1361 | O7: 5 | P7: 60 | Q7: =IF(Tbl_DFR[[#This Row],[Filling Qty]]>=150,"high","normal") -> normal | R7: =IF(AND(Tbl_DFR[[#This Row],[CMP]]="HALDWANI",Tbl_DFR[[#This Row],[Filling Qty]]>=150),"yes","no") -> no | S7: =IF(Tbl_DFR[[#This Row],[Filling Qty]]>=150,"high",IF(Tbl_DFR[[#This Row],[Filling Qty]]>=80,"medium","low")) -> low | T7: =P7+O7 -> 65 | U7: {=_xlfn.IFS(Tbl_DFR[[#This Row],[Filling Qty]]>=150,"HIGH",Tbl_DFR[[#This Row],[Filling Qty]]>=80,"medium",TRUE,"low")} -> low | V7: =IF(OR(Tbl_DFR[[#This Row],[CMP]]="HALDWANI",Tbl_DFR[[#This Row],[CMP]]="DEHRADUN"),"YES","NO") -> YES | W7: 45932 | Y7: 45931 | Z7: =IFERROR(TEXT(Tbl_DFR[[#This Row],[Date of filling]],"mmm"),"WIP") -> Oct | AA7: =IFERROR(YEAR(Tbl_DFR[[#This Row],[Date of filling]]),"WIP") -> 2025 | AB7: =IFERROR(TEXT(Tbl_DFR[[#This Row],[Date of filling]],"ddd"),"WIP") -> Thu | AD7: =_xlfn.XLOOKUP(Tbl_DFR[[#This Row],[SAP]],Site_master[SAP ID],Site_master[ [ TECHNICIAN Name] ],"Not found") -> Kamlesh Mahra | AE7: =LEN(Tbl_DFR[[#This Row],[SAP]]) -> 18 | AF7: =IF(Tbl_DFR[[#This Row],[SAP LENGTH]]=18,"valid","check") -> valid
A8: 4 | B8: DEHRADUN | C8: =UPPER(TRIM(Tbl_DFR[[#This Row],[CMP]])) -> DEHRADUN | D8: Vivek Kumar | E8: UK17CA5176 | F8: ASHISH | G8: I-UW-VKSN-ENB-9145 | H8: 151303 | I8: 45931 | J8: 45932 | K8: =IF(OR(Tbl_DFR[[#This Row],[Date of filling]]="WIP",Tbl_DFR[[#This Row],[Date of Invoice ]]=""),"",Tbl_DFR[[#This Row],[Date of filling]]-Tbl_DFR[[#This Row],[Date of Invoice ]]) -> 1 | L8: =IF(ISNUMBER(Tbl_DFR[[#This Row],[Invoice filling gape]]),"valid","check") -> valid | M8: 9343 | N8: 2821 | O8: 13 | P8: 60 | Q8: =IF(Tbl_DFR[[#This Row],[Filling Qty]]>=150,"high","normal") -> normal | R8: =IF(AND(Tbl_DFR[[#This Row],[CMP]]="HALDWANI",Tbl_DFR[[#This Row],[Filling Qty]]>=150),"yes","no") -> no | S8: =IF(Tbl_DFR[[#This Row],[Filling Qty]]>=150,"high",IF(Tbl_DFR[[#This Row],[Filling Qty]]>=80,"medium","low")) -> low | T8: =P8+O8 -> 73 | U8: {=_xlfn.IFS(Tbl_DFR[[#This Row],[Filling Qty]]>=150,"HIGH",Tbl_DFR[[#This Row],[Filling Qty]]>=80,"medium",TRUE,"low")} -> low | V8: =IF(OR(Tbl_DFR[[#This Row],[CMP]]="HALDWANI",Tbl_DFR[[#This Row],[CMP]]="DEHRADUN"),"YES","NO") -> YES | W8: 45931 | X8: 45931 | Y8: 45931 | Z8: =IFERROR(TEXT(Tbl_DFR[[#This Row],[Date of filling]],"mmm"),"WIP") -> Oct | AA8: =IFERROR(YEAR(Tbl_DFR[[#This Row],[Date of filling]]),"WIP") -> 2025 | AB8: =IFERROR(TEXT(Tbl_DFR[[#This Row],[Date of filling]],"ddd"),"WIP") -> Thu | AD8: =_xlfn.XLOOKUP(Tbl_DFR[[#This Row],[SAP]],Site_master[SAP ID],Site_master[ [ TECHNICIAN Name] ],"Not found") -> Rohit Thakur SLQU | AE8: =LEN(Tbl_DFR[[#This Row],[SAP]]) -> 18 | AF8: =IF(Tbl_DFR[[#This Row],[SAP LENGTH]]=18,"valid","check") -> valid
A9: 4 | B9: HALDWANI | C9: =UPPER(TRIM(Tbl_DFR[[#This Row],[CMP]])) -> HALDWANI | D9: Aashish Rai | E9: UK05CA2368 | F9: GANESH | G9: I-UW-BRIG-ENB-9018 | H9: TXN100125947379 | I9: 45931 | J9: 45931 | K9: =IF(OR(Tbl_DFR[[#This Row],[Date of filling]]="WIP",Tbl_DFR[[#This Row],[Date of Invoice ]]=""),"",Tbl_DFR[[#This Row],[Date of filling]]-Tbl_DFR[[#This Row],[Date of Invoice ]]) -> 0 | L9: =IF(ISNUMBER(Tbl_DFR[[#This Row],[Invoice filling gape]]),"valid","check") -> valid | M9: 9556 | N9: 2590 | O9: 4 | P9: 100 | Q9: =IF(Tbl_DFR[[#This Row],[Filling Qty]]>=150,"high","normal") -> normal | R9: =IF(AND(Tbl_DFR[[#This Row],[CMP]]="HALDWANI",Tbl_DFR[[#This Row],[Filling Qty]]>=150),"yes","no") -> no | S9: =IF(Tbl_DFR[[#This Row],[Filling Qty]]>=150,"high",IF(Tbl_DFR[[#This Row],[Filling Qty]]>=80,"medium","low")) -> medium | T9: =P9+O9 -> 104 | U9: {=_xlfn.IFS(Tbl_DFR[[#This Row],[Filling Qty]]>=150,"HIGH",Tbl_DFR[[#This Row],[Filling Qty]]>=80,"medium",TRUE,"low")} -> medium | V9: =IF(OR(Tbl_DFR[[#This Row],[CMP]]="HALDWANI",Tbl_DFR[[#This Row],[CMP]]="DEHRADUN"),"YES","NO") -> YES | W9: 45931 | Y9: 45931 | Z9: =IFERROR(TEXT(Tbl_DFR[[#This Row],[Date of filling]],"mmm"),"WIP") -> Oct | AA9: =IFERROR(YEAR(Tbl_DFR[[#This Row],[Date of filling]]),"WIP") -> 2025 | AB9: =IFERROR(TEXT(Tbl_DFR[[#This Row],[Date of filling]],"ddd"),"WIP") -> Wed | AD9: =_xlfn.XLOOKUP(Tbl_DFR[[#This Row],[SAP]],Site_master[SAP ID],Site_master[ [ TECHNICIAN Name] ],"Not found") -> Kamlesh Mahra | AE9: =LEN(Tbl_DFR[[#This Row],[SAP]]) -> 18 | AF9: =IF(Tbl_DFR[[#This Row],[SAP LENGTH]]=18,"valid","check") -> valid
A10: 5 | B10: DEHRADUN | C10: =UPPER(TRIM(Tbl_DFR[[#This Row],[CMP]])) -> DEHRADUN | D10: Vivek Kumar | E10: UK17CA5176 | F10: ASHISH | G10: I-UW-VKSN-ENB-9074 | H10: 151030 | I10: 45931 | J10: 45933 | K10: =IF(OR(Tbl_DFR[[#This Row],[Date of filling]]="WIP",Tbl_DFR[[#This Row],[Date of Invoice ]]=""),"",Tbl_DFR[[#This Row],[Date of filling]]-Tbl_DFR[[#This Row],[Date of Invoice ]]) -> 2 | L10: =IF(ISNUMBER(Tbl_DFR[[#This Row],[Invoice filling gape]]),"valid","check") -> valid | M10: 4272 | N10: 507 | O10: 15 | P10: 80 | Q10: =IF(Tbl_DFR[[#This Row],[Filling Qty]]>=150,"high","normal") -> normal | R10: =IF(AND(Tbl_DFR[[#This Row],[CMP]]="HALDWANI",Tbl_DFR[[#This Row],[Filling Qty]]>=150),"yes","no") -> no | S10: =IF(Tbl_DFR[[#This Row],[Filling Qty]]>=150,"high",IF(Tbl_DFR[[#This Row],[Filling Qty]]>=80,"medium","low")) -> medium | T10: =P10+O10 -> 95 | U10: {=_xlfn.IFS(Tbl_DFR[[#This Row],[Filling Qty]]>=150,"HIGH",Tbl_DFR[[#This Row],[Filling Qty]]>=80,"medium",TRUE,"low")} -> medium | V10: =IF(OR(Tbl_DFR[[#This Row],[CMP]]="HALDWANI",Tbl_DFR[[#This Row],[CMP]]="DEHRADUN"),"YES","NO") -> YES | W10: 45931 | X10: 45931 | Y10: 45931 | Z10: =IFERROR(TEXT(Tbl_DFR[[#This Row],[Date of filling]],"mmm"),"WIP") -> Oct | AA10: =IFERROR(YEAR(Tbl_DFR[[#This Row],[Date of filling]]),"WIP") -> 2025 | AB10: =IFERROR(TEXT(Tbl_DFR[[#This Row],[Date of filling]],"ddd"),"WIP") -> Fri | AD10: =_xlfn.XLOOKUP(Tbl_DFR[[#This Row],[SAP]],Site_master[SAP ID],Site_master[ [ TECHNICIAN Name] ],"Not found") -> Sandeep Kumar Saini | AE10: =LEN(Tbl_DFR[[#This Row],[SAP]]) -> 18 | AF10: =IF(Tbl_DFR[[#This Row],[SAP LENGTH]]=18,"valid","check") -> valid
A11: 5 | B11: HALDWANI | C11: =UPPER(TRIM(Tbl_DFR[[#This Row],[CMP]])) -> HALDWANI | D11: Aashish Rai | E11: UK05CA2368 | F11: GANESH | G11: I-UW-BRIG-ENB-9019 | H11: TXN100125947379 | I11: 45931 | J11: 45931 | K11: =IF(OR(Tbl_DFR[[#This Row],[Date of filling]]="WIP",Tbl_DFR[[#This Row],[Date of Invoice ]]=""),"",Tbl_DFR[[#This Row],[Date of filling]]-Tbl_DFR[[#This Row],[Date of Invoice ]]) -> 0 | L11: =IF(ISNUMBER(Tbl_DFR[[#This Row],[Invoice filling gape]]),"valid","check") -> valid | M11: 13703 | N11: 2782 | O11: 42 | P11: 80 | Q11: =IF(Tbl_DFR[[#This Row],[Filling Qty]]>=150,"high","normal") -> normal | R11: =IF(AND(Tbl_DFR[[#This Row],[CMP]]="HALDWANI",Tbl_DFR[[#This Row],[Filling Qty]]>=150),"yes","no") -> no | S11: =IF(Tbl_DFR[[#This Row],[Filling Qty]]>=150,"high",IF(Tbl_DFR[[#This Row],[Filling Qty]]>=80,"medium","low")) -> medium | T11: =P11+O11 -> 122 | U11: {=_xlfn.IFS(Tbl_DFR[[#This Row],[Filling Qty]]>=150,"HIGH",Tbl_DFR[[#This Row],[Filling Qty]]>=80,"medium",TRUE,"low")} -> medium | V11: =IF(OR(Tbl_DFR[[#This Row],[CMP]]="HALDWANI",Tbl_DFR[[#This Row],[CMP]]="DEHRADUN"),"YES","NO") -> YES | W11: 45931 | Y11: 45931 | Z11: =IFERROR(TEXT(Tbl_DFR[[#This Row],[Date of filling]],"mmm"),"WIP") -> Oct | AA11: =IFERROR(YEAR(Tbl_DFR[[#This Row],[Date of filling]]),"WIP") -> 2025 | AB11: =IFERROR(TEXT(Tbl_DFR[[#This Row],[Date of filling]],"ddd"),"WIP") -> Wed | AD11: =_xlfn.XLOOKUP(Tbl_DFR[[#This Row],[SAP]],Site_master[SAP ID],Site_master[ [ TECHNICIAN Name] ],"Not found") -> Kamlesh Mahra | AE11: =LEN(Tbl_DFR[[#This Row],[SAP]]) -> 18 | AF11: =IF(Tbl_DFR[[#This Row],[SAP LENGTH]]=18,"valid","check") -> valid
A12: 6 | B12: DEHRADUN | C12: =UPPER(TRIM(Tbl_DFR[[#This Row],[CMP]])) -> DEHRADUN | D12: Vivek Kumar | E12: UK17CA5176 | F12: ASHISH | G12: I-UW-DRDN-ENB-0612 | H12: 151303 | I12: 45931 | J12: 45932 | K12: =IF(OR(Tbl_DFR[[#This Row],[Date of filling]]="WIP",Tbl_DFR[[#This Row],[Date of Invoice ]]=""),"",Tbl_DFR[[#This Row],[Date of filling]]-Tbl_DFR[[#This Row],[Date of Invoice ]]) -> 1 | L12: =IF(ISNUMBER(Tbl_DFR[[#This Row],[Invoice filling gape]]),"valid","check") -> valid | M12: 12515 | N12: 3069 | O12: 21 | P12: 60 | Q12: =IF(Tbl_DFR[[#This Row],[Filling Qty]]>=150,"high","normal") -> normal | R12: =IF(AND(Tbl_DFR[[#This Row],[CMP]]="HALDWANI",Tbl_DFR[[#This Row],[Filling Qty]]>=150),"yes","no") -> no | S12: =IF(Tbl_DFR[[#This Row],[Filling Qty]]>=150,"high",IF(Tbl_DFR[[#This Row],[Filling Qty]]>=80,"medium","low")) -> low | T12: =P12+O12 -> 81 | U12: {=_xlfn.IFS(Tbl_DFR[[#This Row],[Filling Qty]]>=150,"HIGH",Tbl_DFR[[#This Row],[Filling Qty]]>=80,"medium",TRUE,"low")} -> low | V12: =IF(OR(Tbl_DFR[[#This Row],[CMP]]="HALDWANI",Tbl_DFR[[#This Row],[CMP]]="DEHRADUN"),"YES","NO") -> YES | W12: 45931 | X12: 45931 | Y12: 45931 | Z12: =IFERROR(TEXT(Tbl_DFR[[#This Row],[Date of filling]],"mmm"),"WIP") -> Oct | AA12: =IFERROR(YEAR(Tbl_DFR[[#This Row],[Date of filling]]),"WIP") -> 2025 | AB12: =IFERROR(TEXT(Tbl_DFR[[#This Row],[Date of filling]],"ddd"),"WIP") -> Thu | AD12: =_xlfn.XLOOKUP(Tbl_DFR[[#This Row],[SAP]],Site_master[SAP ID],Site_master[ [ TECHNICIAN Name] ],"Not found") -> Rohit Thakur SLQU | AE12: =LEN(Tbl_DFR[[#This Row],[SAP]]) -> 18 | AF12: =IF(Tbl_DFR[[#This Row],[SAP LENGTH]]=18,"valid","check") -> valid
A13: 6 | B13: HALDWANI | C13: =UPPER(TRIM(Tbl_DFR[[#This Row],[CMP]])) -> HALDWANI | D13: Aashish Rai | E13: UK05CA2368 | F13: GANESH | G13: I-UW-BRIG-ENB-9024 | H13: TXN100125947379 | I13: 45931 | J13: 45931 | K13: =IF(OR(Tbl_DFR[[#This Row],[Date of filling]]="WIP",Tbl_DFR[[#This Row],[Date of Invoice ]]=""),"",Tbl_DFR[[#This Row],[Date of filling]]-Tbl_DFR[[#This Row],[Date of Invoice ]]) -> 0 | L13: =IF(ISNUMBER(Tbl_DFR[[#This Row],[Invoice filling gape]]),"valid","check") -> valid | M13: 9297 | N13: 2475 | O13: 71 | P13: 40 | Q13: =IF(Tbl_DFR[[#This Row],[Filling Qty]]>=150,"high","normal") -> normal | R13: =IF(AND(Tbl_DFR[[#This Row],[CMP]]="HALDWANI",Tbl_DFR[[#This Row],[Filling Qty]]>=150),"yes","no") -> no | S13: =IF(Tbl_DFR[[#This Row],[Filling Qty]]>=150,"high",IF(Tbl_DFR[[#This Row],[Filling Qty]]>=80,"medium","low")) -> low | T13: =P13+O13 -> 111 | U13: {=_xlfn.IFS(Tbl_DFR[[#This Row],[Filling Qty]]>=150,"HIGH",Tbl_DFR[[#This Row],[Filling Qty]]>=80,"medium",TRUE,"low")} -> low | V13: =IF(OR(Tbl_DFR[[#This Row],[CMP]]="HALDWANI",Tbl_DFR[[#This Row],[CMP]]="DEHRADUN"),"YES","NO") -> YES | W13: 45931 | X13: 0.65277778 | Y13: 45931 | Z13: =IFERROR(TEXT(Tbl_DFR[[#This Row],[Date of filling]],"mmm"),"WIP") -> Oct | AA13: =IFERROR(YEAR(Tbl_DFR[[#This Row],[Date of filling]]),"WIP") -> 2025 | AB13: =IFERROR(TEXT(Tbl_DFR[[#This Row],[Date of filling]],"ddd"),"WIP") -> Wed | AC13: KAMLESH SINGH MEHRA | AD13: =_xlfn.XLOOKUP(Tbl_DFR[[#This Row],[SAP]],Site_master[SAP ID],Site_master[ [ TECHNICIAN Name] ],"Not found") -> Kamlesh Mahra | AE13: =LEN(Tbl_DFR[[#This Row],[SAP]]) -> 18 | AF13: =IF(Tbl_DFR[[#This Row],[SAP LENGTH]]=18,"valid","check") -> valid
A14: 7 | B14: DEHRADUN | C14: =UPPER(TRIM(Tbl_DFR[[#This Row],[CMP]])) -> DEHRADUN | D14: Vivek Kumar | E14: UK17CA5176 | F14: ASHISH | G14: I-UW-XXXX-COW-0535 | H14: 151155 | I14: 45931 | J14: 45931 | K14: =IF(OR(Tbl_DFR[[#This Row],[Date of filling]]="WIP",Tbl_DFR[[#This Row],[Date of Invoice ]]=""),"",Tbl_DFR[[#This Row],[Date of filling]]-Tbl_DFR[[#This Row],[Date of Invoice ]]) -> 0 | L14: =IF(ISNUMBER(Tbl_DFR[[#This Row],[Invoice filling gape]]),"valid","check") -> valid | M14: 53384 | N14: 10847 | O14: 20 | P14: 160 | Q14: =IF(Tbl_DFR[[#This Row],[Filling Qty]]>=150,"high","normal") -> high | R14: =IF(AND(Tbl_DFR[[#This Row],[CMP]]="HALDWANI",Tbl_DFR[[#This Row],[Filling Qty]]>=150),"yes","no") -> no | S14: =IF(Tbl_DFR[[#This Row],[Filling Qty]]>=150,"high",IF(Tbl_DFR[[#This Row],[Filling Qty]]>=80,"medium","low")) -> high | T14: =P14+O14 -> 180 | U14: {=_xlfn.IFS(Tbl_DFR[[#This Row],[Filling Qty]]>=150,"HIGH",Tbl_DFR[[#This Row],[Filling Qty]]>=80,"medium",TRUE,"low")} -> HIGH | V14: =IF(OR(Tbl_DFR[[#This Row],[CMP]]="HALDWANI",Tbl_DFR[[#This Row],[CMP]]="DEHRADUN"),"YES","NO") -> YES | W14: 45931 | X14: 45931 | Y14: 45931 | Z14: =IFERROR(TEXT(Tbl_DFR[[#This Row],[Date of filling]],"mmm"),"WIP") -> Oct | AA14: =IFERROR(YEAR(Tbl_DFR[[#This Row],[Date of filling]]),"WIP") -> 2025 | AB14: =IFERROR(TEXT(Tbl_DFR[[#This Row],[Date of filling]],"ddd"),"WIP") -> Wed | AD14: =_xlfn.XLOOKUP(Tbl_DFR[[#This Row],[SAP]],Site_master[SAP ID],Site_master[ [ TECHNICIAN Name] ],"Not found") -> Jitendra Negi | AE14: =LEN(Tbl_DFR[[#This Row],[SAP]]) -> 18 | AF14: =IF(Tbl_DFR[[#This Row],[SAP LENGTH]]=18,"valid","check") -> valid
A15: 7 | B15: HALDWANI | C15: =UPPER(TRIM(Tbl_DFR[[#This Row],[CMP]])) -> HALDWANI | D15: Aashish Rai | E15: UK05CA2368 | F15: GANESH | G15: I-UW-BRIG-ENB-9028 | H15: TXN100125947379 | I15: 45931 | J15: 45932 | K15: =IF(OR(Tbl_DFR[[#This Row],[Date of filling]]="WIP",Tbl_DFR[[#This Row],[Date of Invoice ]]=""),"",Tbl_DFR[[#This Row],[Date of filling]]-Tbl_DFR[[#This Row],[Date of Invoice ]]) -> 1 | L15: =IF(ISNUMBER(Tbl_DFR[[#This Row],[Invoice filling gape]]),"valid","check") -> valid | M15: 2393 | N15: 427 | O15: 42 | P15: 80 | Q15: =IF(Tbl_DFR[[#This Row],[Filling Qty]]>=150,"high","normal") -> normal | R15: =IF(AND(Tbl_DFR[[#This Row],[CMP]]="HALDWANI",Tbl_DFR[[#This Row],[Filling Qty]]>=150),"yes","no") -> no | S15: =IF(Tbl_DFR[[#This Row],[Filling Qty]]>=150,"high",IF(Tbl_DFR[[#This Row],[Filling Qty]]>=80,"medium","low")) -> medium | T15: =P15+O15 -> 122 | U15: {=_xlfn.IFS(Tbl_DFR[[#This Row],[Filling Qty]]>=150,"HIGH",Tbl_DFR[[#This Row],[Filling Qty]]>=80,"medium",TRUE,"low")} -> medium | V15: =IF(OR(Tbl_DFR[[#This Row],[CMP]]="HALDWANI",Tbl_DFR[[#This Row],[CMP]]="DEHRADUN"),"YES","NO") -> YES | W15: 45932 | Y15: 45931 | Z15: =IFERROR(TEXT(Tbl_DFR[[#This Row],[Date of filling]],"mmm"),"WIP") -> Oct | AA15: =IFERROR(YEAR(Tbl_DFR[[#This Row],[Date of filling]]),"WIP") -> 2025 | AB15: =IFERROR(TEXT(Tbl_DFR[[#This Row],[Date of filling]],"ddd"),"WIP") -> Thu | AD15: =_xlfn.XLOOKUP(Tbl_DFR[[#This Row],[SAP]],Site_master[SAP ID],Site_master[ [ TECHNICIAN Name] ],"Not found") -> Kamlesh Mahra | AE15: =LEN(Tbl_DFR[[#This Row],[SAP]]) -> 18 | AF15: =IF(Tbl_DFR[[#This Row],[SAP LENGTH]]=18,"valid","check") -> valid
A16: 8 | B16: DEHRADUN | C16: =UPPER(TRIM(Tbl_DFR[[#This Row],[CMP]])) -> DEHRADUN | D16: Vivek Kumar | E16: UK17CA5597 | F16: ANIL | G16: I-UW-GSLI-ENB-9038 | H16: TXN100126016825 | I16: 45931 | J16: 45932 | K16: =IF(OR(Tbl_DFR[[#This Row],[Date of filling]]="WIP",Tbl_DFR[[#This Row],[Date of Invoice ]]=""),"",Tbl_DFR[[#This Row],[Date of filling]]-Tbl_DFR[[#This Row],[Date of Invoice ]]) -> 1 | L16: =IF(ISNUMBER(Tbl_DFR[[#This Row],[Invoice filling gape]]),"valid","check") -> valid | M16: 5661 | N16: 1602 | O16: 64 | P16: 80 | Q16: =IF(Tbl_DFR[[#This Row],[Filling Qty]]>=150,"high","normal") -> normal | R16: =IF(AND(Tbl_DFR[[#This Row],[CMP]]="HALDWANI",Tbl_DFR[[#This Row],[Filling Qty]]>=150),"yes","no") -> no | S16: =IF(Tbl_DFR[[#This Row],[Filling Qty]]>=150,"high",IF(Tbl_DFR[[#This Row],[Filling Qty]]>=80,"medium","low")) -> medium | T16: =P16+O16 -> 144 | U16: {=_xlfn.IFS(Tbl_DFR[[#This Row],[Filling Qty]]>=150,"HIGH",Tbl_DFR[[#This Row],[Filling Qty]]>=80,"medium",TRUE,"low")} -> medium | V16: =IF(OR(Tbl_DFR[[#This Row],[CMP]]="HALDWANI",Tbl_DFR[[#This Row],[CMP]]="DEHRADUN"),"YES","NO") -> YES | W16: 45931 | X16: 45931 | Y16: 45931 | Z16: =IFERROR(TEXT(Tbl_DFR[[#This Row],[Date of filling]],"mmm"),"WIP") -> Oct | AA16: =IFERROR(YEAR(Tbl_DFR[[#This Row],[Date of filling]]),"WIP") -> 2025 | AB16: =IFERROR(TEXT(Tbl_DFR[[#This Row],[Date of filling]],"ddd"),"WIP") -> Thu | AD16: =_xlfn.XLOOKUP(Tbl_DFR[[#This Row],[SAP]],Site_master[SAP ID],Site_master[ [ TECHNICIAN Name] ],"Not found") -> Amit Pal Singh | AE16: =LEN(Tbl_DFR[[#This Row],[SAP]]) -> 18 | AF16: =IF(Tbl_DFR[[#This Row],[SAP LENGTH]]=18,"valid","check") -> valid
A17: 8 | B17: HALDWANI | C17: =UPPER(TRIM(Tbl_DFR[[#This Row],[CMP]])) -> HALDWANI | D17: Aashish Rai | E17: UK05CA2368 | F17: GANESH | G17: I-UW-BRIG-ILA-0001 | H17: TXN100125947268 | I17: 45931 | J17: 45931 | K17: =IF(OR(Tbl_DFR[[#This Row],[Date of filling]]="WIP",Tbl_DFR[[#This Row],[Date of Invoice ]]=""),"",Tbl_DFR[[#This Row],[Date of filling]]-Tbl_DFR[[#This Row],[Date of Invoice ]]) -> 0 | L17: =IF(ISNUMBER(Tbl_DFR[[#This Row],[Invoice filling gape]]),"valid","check") -> valid | M17: 3789 | N17: 1560 | O17: 50 | P17: 60 | Q17: =IF(Tbl_DFR[[#This Row],[Filling Qty]]>=150,"high","normal") -> normal | R17: =IF(AND(Tbl_DFR[[#This Row],[CMP]]="HALDWANI",Tbl_DFR[[#This Row],[Filling Qty]]>=150),"yes","no") -> no | S17: =IF(Tbl_DFR[[#This Row],[Filling Qty]]>=150,"high",IF(Tbl_DFR[[#This Row],[Filling Qty]]>=80,"medium","low")) -> low | T17: =P17+O17 -> 110 | U17: {=_xlfn.IFS(Tbl_DFR[[#This Row],[Filling Qty]]>=150,"HIGH",Tbl_DFR[[#This Row],[Filling Qty]]>=80,"medium",TRUE,"low")} -> low | V17: =IF(OR(Tbl_DFR[[#This Row],[CMP]]="HALDWANI",Tbl_DFR[[#This Row],[CMP]]="DEHRADUN"),"YES","NO") -> YES | W17: 45931 | Y17: 45931 | Z17: =IFERROR(TEXT(Tbl_DFR[[#This Row],[Date of filling]],"mmm"),"WIP") -> Oct | AA17: =IFERROR(YEAR(Tbl_DFR[[#This Row],[Date of filling]]),"WIP") -> 2025 | AB17: =IFERROR(TEXT(Tbl_DFR[[#This Row],[Date of filling]],"ddd"),"WIP") -> Wed | AD17: =_xlfn.XLOOKUP(Tbl_DFR[[#This Row],[SAP]],Site_master[SAP ID],Site_master[ [ TECHNICIAN Name] ],"Not found") -> Kamlesh Mahra | AE17: =LEN(Tbl_DFR[[#This Row],[SAP]]) -> 18 | AF17: =IF(Tbl_DFR[[#This Row],[SAP LENGTH]]=18,"valid","check") -> valid
A18: 9 | B18: DEHRADUN | C18: =UPPER(TRIM(Tbl_DFR[[#This Row],[CMP]])) -> DEHRADUN | D18: Vivek Kumar | E18: UK17CA5597 | F18: ANIL | G18: I-UW-GSLI-ENB-9076 | H18: TXN100126016825 | I18: 45931 | J18: 45932 | K18: =IF(OR(Tbl_DFR[[#This Row],[Date of filling]]="WIP",Tbl_DFR[[#This Row],[Date of Invoice ]]=""),"",Tbl_DFR[[#This Row],[Date of filling]]-Tbl_DFR[[#This Row],[Date of Invoice ]]) -> 1 | L18: =IF(ISNUMBER(Tbl_DFR[[#This Row],[Invoice filling gape]]),"valid","check") -> valid | M18: 5520 | N18: 1455 | O18: 40 | P18: 80 | Q18: =IF(Tbl_DFR[[#This Row],[Filling Qty]]>=150,"high","normal") -> normal | R18: =IF(AND(Tbl_DFR[[#This Row],[CMP]]="HALDWANI",Tbl_DFR[[#This Row],[Filling Qty]]>=150),"yes","no") -> no | S18: =IF(Tbl_DFR[[#This Row],[Filling Qty]]>=150,"high",IF(Tbl_DFR[[#This Row],[Filling Qty]]>=80,"medium","low")) -> medium | T18: =P18+O18 -> 120 | U18: {=_xlfn.IFS(Tbl_DFR[[#This Row],[Filling Qty]]>=150,"HIGH",Tbl_DFR[[#This Row],[Filling Qty]]>=80,"medium",TRUE,"low")} -> medium | V18: =IF(OR(Tbl_DFR[[#This Row],[CMP]]="HALDWANI",Tbl_DFR[[#This Row],[CMP]]="DEHRADUN"),"YES","NO") -> YES | W18: 45931 | X18: 45931 | Y18: 45931 | Z18: =IFERROR(TEXT(Tbl_DFR[[#This Row],[Date of filling]],"mmm"),"WIP") -> Oct | AA18: =IFERROR(YEAR(Tbl_DFR[[#This Row],[Date of filling]]),"WIP") -> 2025 | AB18: =IFERROR(TEXT(Tbl_DFR[[#This Row],[Date of filling]],"ddd"),"WIP") -> Thu | AD18: =_xlfn.XLOOKUP(Tbl_DFR[[#This Row],[SAP]],Site_master[SAP ID],Site_master[ [ TECHNICIAN Name] ],"Not found") -> Pawan Kumar | AE18: =LEN(Tbl_DFR[[#This Row],[SAP]]) -> 18 | AF18: =IF(Tbl_DFR[[#This Row],[SAP LENGTH]]=18,"valid","check") -> valid
A19: 9 | B19: HALDWANI | C19: =UPPER(TRIM(Tbl_DFR[[#This Row],[CMP]])) -> HALDWANI | D19: Aashish Rai | E19: UP21ET8573 | F19: AMAN | G19: I-UW-BZPR-ENB-9018 | H19: 80958 | I19: 45931 | J19: 45931 | K19: =IF(OR(Tbl_DFR[[#This Row],[Date of filling]]="WIP",Tbl_DFR[[#This Row],[Date of Invoice ]]=""),"",Tbl_DFR[[#This Row],[Date of filling]]-Tbl_DFR[[#This Row],[Date of Invoice ]]) -> 0 | L19: =IF(ISNUMBER(Tbl_DFR[[#This Row],[Invoice filling gape]]),"valid","check") -> valid | M19: 12182 | N19: 2214 | O19: 45 | P19: 40 | Q19: =IF(Tbl_DFR[[#This Row],[Filling Qty]]>=150,"high","normal") -> normal | R19: =IF(AND(Tbl_DFR[[#This Row],[CMP]]="HALDWANI",Tbl_DFR[[#This Row],[Filling Qty]]>=150),"yes","no") -> no | S19: =IF(Tbl_DFR[[#This Row],[Filling Qty]]>=150,"high",IF(Tbl_DFR[[#This Row],[Filling Qty]]>=80,"medium","low")) -> low | T19: =P19+O19 -> 85 | U19: {=_xlfn.IFS(Tbl_DFR[[#This Row],[Filling Qty]]>=150,"HIGH",Tbl_DFR[[#This Row],[Filling Qty]]>=80,"medium",TRUE,"low")} -> low | V19: =IF(OR(Tbl_DFR[[#This Row],[CMP]]="HALDWANI",Tbl_DFR[[#This Row],[CMP]]="DEHRADUN"),"YES","NO") -> YES | W19: 45931 | X19: 0.46458333 | Y19: 45931 | Z19: =IFERROR(TEXT(Tbl_DFR[[#This Row],[Date of filling]],"mmm"),"WIP") -> Oct | AA19: =IFERROR(YEAR(Tbl_DFR[[#This Row],[Date of filling]]),"WIP") -> 2025 | AB19: =IFERROR(TEXT(Tbl_DFR[[#This Row],[Date of filling]],"ddd"),"WIP") -> Wed | AC19: Ankit Kumar | AD19: =_xlfn.XLOOKUP(Tbl_DFR[[#This Row],[SAP]],Site_master[SAP ID],Site_master[ [ TECHNICIAN Name] ],"Not found") -> Kapil Pal | AE19: =LEN(Tbl_DFR[[#This Row],[SAP]]) -> 18 | AF19: =IF(Tbl_DFR[[#This Row],[SAP LENGTH]]=18,"valid","check") -> valid
A20: 10 | B20: DEHRADUN | C20: =UPPER(TRIM(Tbl_DFR[[#This Row],[CMP]])) -> DEHRADUN | D20: Vivek Kumar | E20: UK17CA5597 | F20: ANIL | G20: I-UW-BLRN-ENB-9002 | H20: TXN100126016825 | I20: 45931 | J20: 45932 | K20: =IF(OR(Tbl_DFR[[#This Row],[Date of filling]]="WIP",Tbl_DFR[[#This Row],[Date of Invoice ]]=""),"",Tbl_DFR[[#This Row],[Date of filling]]-Tbl_DFR[[#This Row],[Date of Invoice ]]) -> 1 | L20: =IF(ISNUMBER(Tbl_DFR[[#This Row],[Invoice filling gape]]),"valid","check") -> valid | M20: 3534 | N20: 1102 | O20: 48 | P20: 80 | Q20: =IF(Tbl_DFR[[#This Row],[Filling Qty]]>=150,"high","normal") -> normal | R20: =IF(AND(Tbl_DFR[[#This Row],[CMP]]="HALDWANI",Tbl_DFR[[#This Row],[Filling Qty]]>=150),"yes","no") -> no | S20: =IF(Tbl_DFR[[#This Row],[Filling Qty]]>=150,"high",IF(Tbl_DFR[[#This Row],[Filling Qty]]>=80,"medium","low")) -> medium | T20: =P20+O20 -> 128 | U20: {=_xlfn.IFS(Tbl_DFR[[#This Row],[Filling Qty]]>=150,"HIGH",Tbl_DFR[[#This Row],[Filling Qty]]>=80,"medium",TRUE,"low")} -> medium | V20: =IF(OR(Tbl_DFR[[#This Row],[CMP]]="HALDWANI",Tbl_DFR[[#This Row],[CMP]]="DEHRADUN"),"YES","NO") -> YES | W20: 45931 | X20: 45931 | Y20: 45931 | Z20: =IFERROR(TEXT(Tbl_DFR[[#This Row],[Date of filling]],"mmm"),"WIP") -> Oct | AA20: =IFERROR(YEAR(Tbl_DFR[[#This Row],[Date of filling]]),"WIP") -> 2025 | AB20: =IFERROR(TEXT(Tbl_DFR[[#This Row],[Date of filling]],"ddd"),"WIP") -> Thu | AD20: =_xlfn.XLOOKUP(Tbl_DFR[[#This Row],[SAP]],Site_master[SAP ID],Site_master[ [ TECHNICIAN Name] ],"Not found") -> Ankit Lasiyal | AE20: =LEN(Tbl_DFR[[#This Row],[SAP]]) -> 18 | AF20: =IF(Tbl_DFR[[#This Row],[SAP LENGTH]]=18,"valid","check") -> valid
A21: 10 | B21: HALDWANI | C21: =UPPER(TRIM(Tbl_DFR[[#This Row],[CMP]])) -> HALDWANI | D21: Aashish Rai | E21: UP21ET8573 | F21: AMAN | G21: I-UW-BZPR-ENB-9022 | H21: 80853 | I21: 45931 | J21: 45931 | K21: =IF(OR(Tbl_DFR[[#This Row],[Date of filling]]="WIP",Tbl_DFR[[#This Row],[Date of Invoice ]]=""),"",Tbl_DFR[[#This Row],[Date of filling]]-Tbl_DFR[[#This Row],[Date of Invoice ]]) -> 0 | L21: =IF(ISNUMBER(Tbl_DFR[[#This Row],[Invoice filling gape]]),"valid","check") -> valid | M21: 16080 | N21: 4430 | O21: 17 | P21: 140 | Q21: =IF(Tbl_DFR[[#This Row],[Filling Qty]]>=150,"high","normal") -> normal | R21: =IF(AND(Tbl_DFR[[#This Row],[CMP]]="HALDWANI",Tbl_DFR[[#This Row],[Filling Qty]]>=150),"yes","no") -> no | S21: =IF(Tbl_DFR[[#This Row],[Filling Qty]]>=150,"high",IF(Tbl_DFR[[#This Row],[Filling Qty]]>=80,"medium","low")) -> medium | T21: =P21+O21 -> 157 | U21: {=_xlfn.IFS(Tbl_DFR[[#This Row],[Filling Qty]]>=150,"HIGH",Tbl_DFR[[#This Row],[Filling Qty]]>=80,"medium",TRUE,"low")} -> medium | V21: =IF(OR(Tbl_DFR[[#This Row],[CMP]]="HALDWANI",Tbl_DFR[[#This Row],[CMP]]="DEHRADUN"),"YES","NO") -> YES | W21: 45931 | Y21: 45931 | Z21: =IFERROR(TEXT(Tbl_DFR[[#This Row],[Date of filling]],"mmm"),"WIP") -> Oct | AA21: =IFERROR(YEAR(Tbl_DFR[[#This Row],[Date of filling]]),"WIP") -> 2025 | AB21: =IFERROR(TEXT(Tbl_DFR[[#This Row],[Date of filling]],"ddd"),"WIP") -> Wed | AD21: =_xlfn.XLOOKUP(Tbl_DFR[[#This Row],[SAP]],Site_master[SAP ID],Site_master[ [ TECHNICIAN Name] ],"Not found") -> Kapil Pal | AE21: =LEN(Tbl_DFR[[#This Row],[SAP]]) -> 18 | AF21: =IF(Tbl_DFR[[#This Row],[SAP LENGTH]]=18,"valid","check") -> valid
A22: 11 | B22: DEHRADUN | C22: =UPPER(TRIM(Tbl_DFR[[#This Row],[CMP]])) -> DEHRADUN | D22: Vivek Kumar | E22: UK17CA5597 | F22: ANIL | G22: I-UW-JHDR-ENB-9002 | H22: TXN100126016826 | I22: 45931 | J22: 45933 | K22: =IF(OR(Tbl_DFR[[#This Row],[Date of filling]]="WIP",Tbl_DFR[[#This Row],[Date of Invoice ]]=""),"",Tbl_DFR[[#This Row],[Date of filling]]-Tbl_DFR[[#This Row],[Date of Invoice ]]) -> 2 | L22: =IF(ISNUMBER(Tbl_DFR[[#This Row],[Invoice filling gape]]),"valid","check") -> valid | M22: 3713 | N22: 771 | O22: 66 | P22: 80 | Q22: =IF(Tbl_DFR[[#This Row],[Filling Qty]]>=150,"high","normal") -> normal | R22: =IF(AND(Tbl_DFR[[#This Row],[CMP]]="HALDWANI",Tbl_DFR[[#This Row],[Filling Qty]]>=150),"yes","no") -> no | S22: =IF(Tbl_DFR[[#This Row],[Filling Qty]]>=150,"high",IF(Tbl_DFR[[#This Row],[Filling Qty]]>=80,"medium","low")) -> medium | T22: =P22+O22 -> 146 | U22: {=_xlfn.IFS(Tbl_DFR[[#This Row],[Filling Qty]]>=150,"HIGH",Tbl_DFR[[#This Row],[Filling Qty]]>=80,"medium",TRUE,"low")} -> medium | V22: =IF(OR(Tbl_DFR[[#This Row],[CMP]]="HALDWANI",Tbl_DFR[[#This Row],[CMP]]="DEHRADUN"),"YES","NO") -> YES | W22: 45931 | X22: 45931 | Y22: 45931 | Z22: =IFERROR(TEXT(Tbl_DFR[[#This Row],[Date of filling]],"mmm"),"WIP") -> Oct | AA22: =IFERROR(YEAR(Tbl_DFR[[#This Row],[Date of filling]]),"WIP") -> 2025 | AB22: =IFERROR(TEXT(Tbl_DFR[[#This Row],[Date of filling]],"ddd"),"WIP") -> Fri | AD22: =_xlfn.XLOOKUP(Tbl_DFR[[#This Row],[SAP]],Site_master[SAP ID],Site_master[ [ TECHNICIAN Name] ],"Not found") -> Ashok Singh Ramola | AE22: =LEN(Tbl_DFR[[#This Row],[SAP]]) -> 18 | AF22: =IF(Tbl_DFR[[#This Row],[SAP LENGTH]]=18,"valid","check") -> valid
A23: 11 | B23: HALDWANI | C23: =UPPER(TRIM(Tbl_DFR[[#This Row],[CMP]])) -> HALDWANI | D23: Aashish Rai | E23: UP21ET8573 | F23: AMAN | G23: I-UW-BZPR-ENB-9025 | H23: 80853 | I23: 45931 | J23: 45931 | K23: =IF(OR(Tbl_DFR[[#This Row],[Date of filling]]="WIP",Tbl_DFR[[#This Row],[Date of Invoice ]]=""),"",Tbl_DFR[[#This Row],[Date of filling]]-Tbl_DFR[[#This Row],[Date of Invoice ]]) -> 0 | L23: =IF(ISNUMBER(Tbl_DFR[[#This Row],[Invoice filling gape]]),"valid","check") -> valid | M23: 9551 | N23: 1857 | O23: 18 | P23: 60 | Q23: =IF(Tbl_DFR[[#This Row],[Filling Qty]]>=150,"high","normal") -> normal | R23: =IF(AND(Tbl_DFR[[#This Row],[CMP]]="HALDWANI",Tbl_DFR[[#This Row],[Filling Qty]]>=150),"yes","no") -> no | S23: =IF(Tbl_DFR[[#This Row],[Filling Qty]]>=150,"high",IF(Tbl_DFR[[#This Row],[Filling Qty]]>=80,"medium","low")) -> low | T23: =P23+O23 -> 78 | U23: {=_xlfn.IFS(Tbl_DFR[[#This Row],[Filling Qty]]>=150,"HIGH",Tbl_DFR[[#This Row],[Filling Qty]]>=80,"medium",TRUE,"low")} -> low | V23: =IF(OR(Tbl_DFR[[#This Row],[CMP]]="HALDWANI",Tbl_DFR[[#This Row],[CMP]]="DEHRADUN"),"YES","NO") -> YES | W23: 45931 | Y23: 45931 | Z23: =IFERROR(TEXT(Tbl_DFR[[#This Row],[Date of filling]],"mmm"),"WIP") -> Oct | AA23: =IFERROR(YEAR(Tbl_DFR[[#This Row],[Date of filling]]),"WIP") -> 2025 | AB23: =IFERROR(TEXT(Tbl_DFR[[#This Row],[Date of filling]],"ddd"),"WIP") -> Wed | AD23: =_xlfn.XLOOKUP(Tbl_DFR[[#This Row],[SAP]],Site_master[SAP ID],Site_master[ [ TECHNICIAN Name] ],"Not found") -> Kapil Pal | AE23: =LEN(Tbl_DFR[[#This Row],[SAP]]) -> 18 | AF23: =IF(Tbl_DFR[[#This Row],[SAP LENGTH]]=18,"valid","check") -> valid
A24: 12 | B24: DEHRADUN | C24: =UPPER(TRIM(Tbl_DFR[[#This Row],[CMP]])) -> DEHRADUN | D24: Vivek Kumar | E24: UK17CA 5823 | F24: VINAY | G24: I-UW-CHRD-ENB-9038 | H24: TXN100126168123 | I24: 45932 | J24: 45933 | K24: =IF(OR(Tbl_DFR[[#This Row],[Date of filling]]="WIP",Tbl_DFR[[#This Row],[Date of Invoice ]]=""),"",Tbl_DFR[[#This Row],[Date of filling]]-Tbl_DFR[[#This Row],[Date of Invoice ]]) -> 1 | L24: =IF(ISNUMBER(Tbl_DFR[[#This Row],[Invoice filling gape]]),"valid","check") -> valid | M24: 1089 | N24: 242 | O24: 124 | P24: 100 | Q24: =IF(Tbl_DFR[[#This Row],[Filling Qty]]>=150,"high","normal") -> normal | R24: =IF(AND(Tbl_DFR[[#This Row],[CMP]]="HALDWANI",Tbl_DFR[[#This Row],[Filling Qty]]>=150),"yes","no") -> no | S24: =IF(Tbl_DFR[[#This Row],[Filling Qty]]>=150,"high",IF(Tbl_DFR[[#This Row],[Filling Qty]]>=80,"medium","low")) -> medium | T24: =P24+O24 -> 224 | U24: {=_xlfn.IFS(Tbl_DFR[[#This Row],[Filling Qty]]>=150,"HIGH",Tbl_DFR[[#This Row],[Filling Qty]]>=80,"medium",TRUE,"low")} -> medium | V24: =IF(OR(Tbl_DFR[[#This Row],[CMP]]="HALDWANI",Tbl_DFR[[#This Row],[CMP]]="DEHRADUN"),"YES","NO") -> YES | W24: 45932 | X24: 45931 | Y24: 45931 | Z24: =IFERROR(TEXT(Tbl_DFR[[#This Row],[Date of filling]],"mmm"),"WIP") -> Oct | AA24: =IFERROR(YEAR(Tbl_DFR[[#This Row],[Date of filling]]),"WIP") -> 2025 | AB24: =IFERROR(TEXT(Tbl_DFR[[#This Row],[Date of filling]],"ddd"),"WIP") -> Fri | AD24: =_xlfn.XLOOKUP(Tbl_DFR[[#This Row],[SAP]],Site_master[SAP ID],Site_master[ [ TECHNICIAN Name] ],"Not found") -> Jagat Singh Chauhan | AE24: =LEN(Tbl_DFR[[#This Row],[SAP]]) -> 18 | AF24: =IF(Tbl_DFR[[#This Row],[SAP LENGTH]]=18,"valid","check") -> valid
A25: 12 | B25: HALDWANI | C25: =UPPER(TRIM(Tbl_DFR[[#This Row],[CMP]])) -> HALDWANI | D25: Aashish Rai | E25: UP21ET8573 | F25: AMAN | G25: I-UW-BZPR-ENB-9026 | H25: 80853 | I25: 45931 | J25: 45931 | K25: =IF(OR(Tbl_DFR[[#This Row],[Date of filling]]="WIP",Tbl_DFR[[#This Row],[Date of Invoice ]]=""),"",Tbl_DFR[[#This Row],[Date of filling]]-Tbl_DFR[[#This Row],[Date of Invoice ]]) -> 0 | L25: =IF(ISNUMBER(Tbl_DFR[[#This Row],[Invoice filling gape]]),"valid","check") -> valid | M25: 11912 | N25: 2712 | O25: 28 | P25: 120 | Q25: =IF(Tbl_DFR[[#This Row],[Filling Qty]]>=150,"high","normal") -> normal | R25: =IF(AND(Tbl_DFR[[#This Row],[CMP]]="HALDWANI",Tbl_DFR[[#This Row],[Filling Qty]]>=150),"yes","no") -> no | S25: =IF(Tbl_DFR[[#This Row],[Filling Qty]]>=150,"high",IF(Tbl_DFR[[#This Row],[Filling Qty]]>=80,"medium","low")) -> medium | T25: =P25+O25 -> 148 | U25: {=_xlfn.IFS(Tbl_DFR[[#This Row],[Filling Qty]]>=150,"HIGH",Tbl_DFR[[#This Row],[Filling Qty]]>=80,"medium",TRUE,"low")} -> medium | V25: =IF(OR(Tbl_DFR[[#This Row],[CMP]]="HALDWANI",Tbl_DFR[[#This Row],[CMP]]="DEHRADUN"),"YES","NO") -> YES | W25: 45931 | X25: 0.60347222 | Y25: 45931 | Z25: =IFERROR(TEXT(Tbl_DFR[[#This Row],[Date of filling]],"mmm"),"WIP") -> Oct | AA25: =IFERROR(YEAR(Tbl_DFR[[#This Row],[Date of filling]]),"WIP") -> 2025 | AB25: =IFERROR(TEXT(Tbl_DFR[[#This Row],[Date of filling]],"ddd"),"WIP") -> Wed | AC25: Ankit | AD25: =_xlfn.XLOOKUP(Tbl_DFR[[#This Row],[SAP]],Site_master[SAP ID],Site_master[ [ TECHNICIAN Name] ],"Not found") -> Kapil Pal | AE25: =LEN(Tbl_DFR[[#This Row],[SAP]]) -> 18 | AF25: =IF(Tbl_DFR[[#This Row],[SAP LENGTH]]=18,"valid","check") -> valid
A26: 13 | B26: DEHRADUN | C26: =UPPER(TRIM(Tbl_DFR[[#This Row],[CMP]])) -> DEHRADUN | D26: Vivek Kumar | E26: UK17CA 5823 | F26: VINAY | G26: I-UW-MORI-ENB-9004 | H26: TXN100126168017 | I26: 45932 | J26: 45931 | K26: =IF(OR(Tbl_DFR[[#This Row],[Date of filling]]="WIP",Tbl_DFR[[#This Row],[Date of Invoice ]]=""),"",Tbl_DFR[[#This Row],[Date of filling]]-Tbl_DFR[[#This Row],[Date of Invoice ]]) -> -1 | L26: =IF(ISNUMBER(Tbl_DFR[[#This Row],[Invoice filling gape]]),"valid","check") -> valid | M26: 3935 | N26: 568 | O26: 0 | P26: 200 | Q26: =IF(Tbl_DFR[[#This Row],[Filling Qty]]>=150,"high","normal") -> high | R26: =IF(AND(Tbl_DFR[[#This Row],[CMP]]="HALDWANI",Tbl_DFR[[#This Row],[Filling Qty]]>=150),"yes","no") -> no | S26: =IF(Tbl_DFR[[#This Row],[Filling Qty]]>=150,"high",IF(Tbl_DFR[[#This Row],[Filling Qty]]>=80,"medium","low")) -> high | T26: =P26+O26 -> 200 | U26: {=_xlfn.IFS(Tbl_DFR[[#This Row],[Filling Qty]]>=150,"HIGH",Tbl_DFR[[#This Row],[Filling Qty]]>=80,"medium",TRUE,"low")} -> HIGH | V26: =IF(OR(Tbl_DFR[[#This Row],[CMP]]="HALDWANI",Tbl_DFR[[#This Row],[CMP]]="DEHRADUN"),"YES","NO") -> YES | W26: 45932 | X26: 45931 | Y26: 45931 | Z26: =IFERROR(TEXT(Tbl_DFR[[#This Row],[Date of filling]],"mmm"),"WIP") -> Oct | AA26: =IFERROR(YEAR(Tbl_DFR[[#This Row],[Date of filling]]),"WIP") -> 2025 | AB26: =IFERROR(TEXT(Tbl_DFR[[#This Row],[Date of filling]],"ddd"),"WIP") -> Wed | AD26: =_xlfn.XLOOKUP(Tbl_DFR[[#This Row],[SAP]],Site_master[SAP ID],Site_master[ [ TECHNICIAN Name] ],"Not found") -> Sandeep Kumar MORI | AE26: =LEN(Tbl_DFR[[#This Row],[SAP]]) -> 18 | AF26: =IF(Tbl_DFR[[#This Row],[SAP LENGTH]]=18,"valid","check") -> valid
A27: 13 | B27: HALDWANI | C27: =UPPER(TRIM(Tbl_DFR[[#This Row],[CMP]])) -> HALDWANI | D27: Aashish Rai | E27: UP21ET8573 | F27: AMAN | G27: I-UW-BZPR-ENB-9040 | H27: 80958 | I27: 45931 | J27: 45931 | K27: =IF(OR(Tbl_DFR[[#This Row],[Date of filling]]="WIP",Tbl_DFR[[#This Row],[Date of Invoice ]]=""),"",Tbl_DFR[[#This Row],[Date of filling]]-Tbl_DFR[[#This Row],[Date of Invoice ]]) -> 0 | L27: =IF(ISNUMBER(Tbl_DFR[[#This Row],[Invoice filling gape]]),"valid","check") -> valid | M27: 3694 | N27: 605 | O27: 45 | P27: 40 | Q27: =IF(Tbl_DFR[[#This Row],[Filling Qty]]>=150,"high","normal") -> normal | R27: =IF(AND(Tbl_DFR[[#This Row],[CMP]]="HALDWANI",Tbl_DFR[[#This Row],[Filling Qty]]>=150),"yes","no") -> no | S27: =IF(Tbl_DFR[[#This Row],[Filling Qty]]>=150,"high",IF(Tbl_DFR[[#This Row],[Filling Qty]]>=80,"medium","low")) -> low | T27: =P27+O27 -> 85 | U27: {=_xlfn.IFS(Tbl_DFR[[#This Row],[Filling Qty]]>=150,"HIGH",Tbl_DFR[[#This Row],[Filling Qty]]>=80,"medium",TRUE,"low")} -> low | V27: =IF(OR(Tbl_DFR[[#This Row],[CMP]]="HALDWANI",Tbl_DFR[[#This Row],[CMP]]="DEHRADUN"),"YES","NO") -> YES | W27: 45931 | X27: 0.58541667 | Y27: 45931 | Z27: =IFERROR(TEXT(Tbl_DFR[[#This Row],[Date of filling]],"mmm"),"WIP") -> Oct | AA27: =IFERROR(YEAR(Tbl_DFR[[#This Row],[Date of filling]]),"WIP") -> 2025 | AB27: =IFERROR(TEXT(Tbl_DFR[[#This Row],[Date of filling]],"ddd"),"WIP") -> Wed | AC27: Kapil Pal | AD27: =_xlfn.XLOOKUP(Tbl_DFR[[#This Row],[SAP]],Site_master[SAP ID],Site_master[ [ TECHNICIAN Name] ],"Not found") -> Kapil Pal | AE27: =LEN(Tbl_DFR[[#This Row],[SAP]]) -> 18 | AF27: =IF(Tbl_DFR[[#This Row],[SAP LENGTH]]=18,"valid","check") -> valid
A28: 14 | B28: DEHRADUN | C28: =UPPER(TRIM(Tbl_DFR[[#This Row],[CMP]])) -> DEHRADUN | D28: Vivek Kumar | E28: UK17CA 5823 | F28: VINAY | G28: I-UW-MORI-ENB-9009 | H28: TXN100126172174 | I28: 45932 | J28: 45932 | K28: =IF(OR(Tbl_DFR[[#This Row],[Date of filling]]="WIP",Tbl_DFR[[#This Row],[Date of Invoice ]]=""),"",Tbl_DFR[[#This Row],[Date of filling]]-Tbl_DFR[[#This Row],[Date of Invoice ]]) -> 0 | L28: =IF(ISNUMBER(Tbl_DFR[[#This Row],[Invoice filling gape]]),"valid","check") -> valid | M28: 27822 | N28: 5555 | O28: 0 | P28: 200 | Q28: =IF(Tbl_DFR[[#This Row],[Filling Qty]]>=150,"high","normal") -> high | R28: =IF(AND(Tbl_DFR[[#This Row],[CMP]]="HALDWANI",Tbl_DFR[[#This Row],[Filling Qty]]>=150),"yes","no") -> no | S28: =IF(Tbl_DFR[[#This Row],[Filling Qty]]>=150,"high",IF(Tbl_DFR[[#This Row],[Filling Qty]]>=80,"medium","low")) -> high | T28: =P28+O28 -> 200 | U28: {=_xlfn.IFS(Tbl_DFR[[#This Row],[Filling Qty]]>=150,"HIGH",Tbl_DFR[[#This Row],[Filling Qty]]>=80,"medium",TRUE,"low")} -> HIGH | V28: =IF(OR(Tbl_DFR[[#This Row],[CMP]]="HALDWANI",Tbl_DFR[[#This Row],[CMP]]="DEHRADUN"),"YES","NO") -> YES | W28: 45932 | X28: 45931 | Y28: 45931 | Z28: =IFERROR(TEXT(Tbl_DFR[[#This Row],[Date of filling]],"mmm"),"WIP") -> Oct | AA28: =IFERROR(YEAR(Tbl_DFR[[#This Row],[Date of filling]]),"WIP") -> 2025 | AB28: =IFERROR(TEXT(Tbl_DFR[[#This Row],[Date of filling]],"ddd"),"WIP") -> Thu | AD28: =_xlfn.XLOOKUP(Tbl_DFR[[#This Row],[SAP]],Site_master[SAP ID],Site_master[ [ TECHNICIAN Name] ],"Not found") -> Sandeep Kumar MORI | AE28: =LEN(Tbl_DFR[[#This Row],[SAP]]) -> 18 | AF28: =IF(Tbl_DFR[[#This Row],[SAP LENGTH]]=18,"valid","check") -> valid
A29: 14 | B29: HALDWANI | C29: =UPPER(TRIM(Tbl_DFR[[#This Row],[CMP]])) -> HALDWANI | D29: Aashish Rai | E29: UP21ET8573 | F29: AMAN | G29: I-UW-BZPR-ENB-9041 | H29: 80958 | I29: 45931 | J29: 45932 | K29: =IF(OR(Tbl_DFR[[#This Row],[Date of filling]]="WIP",Tbl_DFR[[#This Row],[Date of Invoice ]]=""),"",Tbl_DFR[[#This Row],[Date of filling]]-Tbl_DFR[[#This Row],[Date of Invoice ]]) -> 1 | L29: =IF(ISNUMBER(Tbl_DFR[[#This Row],[Invoice filling gape]]),"valid","check") -> valid | M29: 10444 | N29: 3251 | O29: 30 | P29: 40 | Q29: =IF(Tbl_DFR[[#This Row],[Filling Qty]]>=150,"high","normal") -> normal | R29: =IF(AND(Tbl_DFR[[#This Row],[CMP]]="HALDWANI",Tbl_DFR[[#This Row],[Filling Qty]]>=150),"yes","no") -> no | S29: =IF(Tbl_DFR[[#This Row],[Filling Qty]]>=150,"high",IF(Tbl_DFR[[#This Row],[Filling Qty]]>=80,"medium","low")) -> low | T29: =P29+O29 -> 70 | U29: {=_xlfn.IFS(Tbl_DFR[[#This Row],[Filling Qty]]>=150,"HIGH",Tbl_DFR[[#This Row],[Filling Qty]]>=80,"medium",TRUE,"low")} -> low | V29: =IF(OR(Tbl_DFR[[#This Row],[CMP]]="HALDWANI",Tbl_DFR[[#This Row],[CMP]]="DEHRADUN"),"YES","NO") -> YES | W29: 45932 | Y29: 45931 | Z29: =IFERROR(TEXT(Tbl_DFR[[#This Row],[Date of filling]],"mmm"),"WIP") -> Oct | AA29: =IFERROR(YEAR(Tbl_DFR[[#This Row],[Date of filling]]),"WIP") -> 2025 | AB29: =IFERROR(TEXT(Tbl_DFR[[#This Row],[Date of filling]],"ddd"),"WIP") -> Thu | AD29: =_xlfn.XLOOKUP(Tbl_DFR[[#This Row],[SAP]],Site_master[SAP ID],Site_master[ [ TECHNICIAN Name] ],"Not found") -> Kapil Pal | AE29: =LEN(Tbl_DFR[[#This Row],[SAP]]) -> 18 | AF29: =IF(Tbl_DFR[[#This Row],[SAP LENGTH]]=18,"valid","check") -> valid
A30: 15 | B30: DEHRADUN | C30: =UPPER(TRIM(Tbl_DFR[[#This Row],[CMP]])) -> DEHRADUN | D30: Vivek Kumar | E30: UK17CA 5823 | F30: VINAY | G30: I-UW-SAKI-ENB-9008 | H30: TXN100126172174 | I30: 45932 | J30: 45932 | K30: =IF(OR(Tbl_DFR[[#This Row],[Date of filling]]="WIP",Tbl_DFR[[#This Row],[Date of Invoice ]]=""),"",Tbl_DFR[[#This Row],[Date of filling]]-Tbl_DFR[[#This Row],[Date of Invoice ]]) -> 0 | L30: =IF(ISNUMBER(Tbl_DFR[[#This Row],[Invoice filling gape]]),"valid","check") -> valid | M30: 13002 | N30: 2030 | O30: 58 | P30: 140 | Q30: =IF(Tbl_DFR[[#This Row],[Filling Qty]]>=150,"high","normal") -> normal | R30: =IF(AND(Tbl_DFR[[#This Row],[CMP]]="HALDWANI",Tbl_DFR[[#This Row],[Filling Qty]]>=150),"yes","no") -> no | S30: =IF(Tbl_DFR[[#This Row],[Filling Qty]]>=150,"high",IF(Tbl_DFR[[#This Row],[Filling Qty]]>=80,"medium","low")) -> medium | T30: =P30+O30 -> 198 | U30: {=_xlfn.IFS(Tbl_DFR[[#This Row],[Filling Qty]]>=150,"HIGH",Tbl_DFR[[#This Row],[Filling Qty]]>=80,"medium",TRUE,"low")} -> medium | V30: =IF(OR(Tbl_DFR[[#This Row],[CMP]]="HALDWANI",Tbl_DFR[[#This Row],[CMP]]="DEHRADUN"),"YES","NO") -> YES | W30: 45932 | X30: 45931 | Y30: 45931 | Z30: =IFERROR(TEXT(Tbl_DFR[[#This Row],[Date of filling]],"mmm"),"WIP") -> Oct | AA30: =IFERROR(YEAR(Tbl_DFR[[#This Row],[Date of filling]]),"WIP") -> 2025 | AB30: =IFERROR(TEXT(Tbl_DFR[[#This Row],[Date of filling]],"ddd"),"WIP") -> Thu | AD30: =_xlfn.XLOOKUP(Tbl_DFR[[#This Row],[SAP]],Site_master[SAP ID],Site_master[ [ TECHNICIAN Name] ],"Not found") -> Sandeep Kumar MORI | AE30: =LEN(Tbl_DFR[[#This Row],[SAP]]) -> 18 | AF30: =IF(Tbl_DFR[[#This Row],[SAP LENGTH]]=18,"valid","check") -> valid
A31: 15 | B31: HALDWANI | C31: =UPPER(TRIM(Tbl_DFR[[#This Row],[CMP]])) -> HALDWANI | D31: Aashish Rai | E31: UP21ET8573 | F31: AMAN | G31: I-UW-BZPR-ENB-9042 | H31: 80853 | I31: 45931 | J31: 45931 | K31: =IF(OR(Tbl_DFR[[#This Row],[Date of filling]]="WIP",Tbl_DFR[[#This Row],[Date of Invoice ]]=""),"",Tbl_DFR[[#This Row],[Date of filling]]-Tbl_DFR[[#This Row],[Date of Invoice ]]) -> 0 | L31: =IF(ISNUMBER(Tbl_DFR[[#This Row],[Invoice filling gape]]),"valid","check") -> valid | M31: 5958 | N31: 1228 | O31: 21 | P31: 60 | Q31: =IF(Tbl_DFR[[#This Row],[Filling Qty]]>=150,"high","normal") -> normal | R31: =IF(AND(Tbl_DFR[[#This Row],[CMP]]="HALDWANI",Tbl_DFR[[#This Row],[Filling Qty]]>=150),"yes","no") -> no | S31: =IF(Tbl_DFR[[#This Row],[Filling Qty]]>=150,"high",IF(Tbl_DFR[[#This Row],[Filling Qty]]>=80,"medium","low")) -> low | T31: =P31+O31 -> 81 | U31: {=_xlfn.IFS(Tbl_DFR[[#This Row],[Filling Qty]]>=150,"HIGH",Tbl_DFR[[#This Row],[Filling Qty]]>=80,"medium",TRUE,"low")} -> low | V31: =IF(OR(Tbl_DFR[[#This Row],[CMP]]="HALDWANI",Tbl_DFR[[#This Row],[CMP]]="DEHRADUN"),"YES","NO") -> YES | W31: 45931 | Y31: 45931 | Z31: =IFERROR(TEXT(Tbl_DFR[[#This Row],[Date of filling]],"mmm"),"WIP") -> Oct | AA31: =IFERROR(YEAR(Tbl_DFR[[#This Row],[Date of filling]]),"WIP") -> 2025 | AB31: =IFERROR(TEXT(Tbl_DFR[[#This Row],[Date of filling]],"ddd"),"WIP") -> Wed | AD31: =_xlfn.XLOOKUP(Tbl_DFR[[#This Row],[SAP]],Site_master[SAP ID],Site_master[ [ TECHNICIAN Name] ],"Not found") -> Kapil Pal | AE31: =LEN(Tbl_DFR[[#This Row],[SAP]]) -> 18 | AF31: =IF(Tbl_DFR[[#This Row],[SAP LENGTH]]=18,"valid","check") -> valid
A32: 16 | B32: DEHRADUN | C32: =UPPER(TRIM(Tbl_DFR[[#This Row],[CMP]])) -> DEHRADUN | D32: Vivek Kumar | E32: UK17CA 5823 | F32: VINAY | G32: I-UW-MORI-ENB-9018 | H32: TXN100126172174 | I32: 45932 | J32: 45932 | K32: =IF(OR(Tbl_DFR[[#This Row],[Date of filling]]="WIP",Tbl_DFR[[#This Row],[Date of Invoice ]]=""),"",Tbl_DFR[[#This Row],[Date of filling]]-Tbl_DFR[[#This Row],[Date of Invoice ]]) -> 0 | L32: =IF(ISNUMBER(Tbl_DFR[[#This Row],[Invoice filling gape]]),"valid","check") -> valid | M32: 6603 | N32: 1354 | O32: 95 | P32: 100 | Q32: =IF(Tbl_DFR[[#This Row],[Filling Qty]]>=150,"high","normal") -> normal | R32: =IF(AND(Tbl_DFR[[#This Row],[CMP]]="HALDWANI",Tbl_DFR[[#This Row],[Filling Qty]]>=150),"yes","no") -> no | S32: =IF(Tbl_DFR[[#This Row],[Filling Qty]]>=150,"high",IF(Tbl_DFR[[#This Row],[Filling Qty]]>=80,"medium","low")) -> medium | T32: =P32+O32 -> 195 | U32: {=_xlfn.IFS(Tbl_DFR[[#This Row],[Filling Qty]]>=150,"HIGH",Tbl_DFR[[#This Row],[Filling Qty]]>=80,"medium",TRUE,"low")} -> medium | V32: =IF(OR(Tbl_DFR[[#This Row],[CMP]]="HALDWANI",Tbl_DFR[[#This Row],[CMP]]="DEHRADUN"),"YES","NO") -> YES | W32: 45932 | X32: 45931 | Y32: 45931 | Z32: =IFERROR(TEXT(Tbl_DFR[[#This Row],[Date of filling]],"mmm"),"WIP") -> Oct | AA32: =IFERROR(YEAR(Tbl_DFR[[#This Row],[Date of filling]]),"WIP") -> 2025 | AB32: =IFERROR(TEXT(Tbl_DFR[[#This Row],[Date of filling]],"ddd"),"WIP") -> Thu | AD32: =_xlfn.XLOOKUP(Tbl_DFR[[#This Row],[SAP]],Site_master[SAP ID],Site_master[ [ TECHNICIAN Name] ],"Not found") -> Yashpal Bhandari | AE32: =LEN(Tbl_DFR[[#This Row],[SAP]]) -> 18 | AF32: =IF(Tbl_DFR[[#This Row],[SAP LENGTH]]=18,"valid","check") -> valid
A33: 16 | B33: HALDWANI | C33: =UPPER(TRIM(Tbl_DFR[[#This Row],[CMP]])) -> HALDWANI | D33: Aashish Rai | E33: UP21ET8573 | F33: AMAN | G33: I-UW-BZPR-ENB-9048 | H33: 80958 | I33: 45931 | J33: 45931 | K33: =IF(OR(Tbl_DFR[[#This Row],[Date of filling]]="WIP",Tbl_DFR[[#This Row],[Date of Invoice ]]=""),"",Tbl_DFR[[#This Row],[Date of filling]]-Tbl_DFR[[#This Row],[Date of Invoice ]]) -> 0 | L33: =IF(ISNUMBER(Tbl_DFR[[#This Row],[Invoice filling gape]]),"valid","check") -> valid | M33: 6593 | N33: 1394 | O33: 65 | P33: 40 | Q33: =IF(Tbl_DFR[[#This Row],[Filling Qty]]>=150,"high","normal") -> normal | R33: =IF(AND(Tbl_DFR[[#This Row],[CMP]]="HALDWANI",Tbl_DFR[[#This Row],[Filling Qty]]>=150),"yes","no") -> no | S33: =IF(Tbl_DFR[[#This Row],[Filling Qty]]>=150,"high",IF(Tbl_DFR[[#This Row],[Filling Qty]]>=80,"medium","low")) -> low | T33: =P33+O33 -> 105 | U33: {=_xlfn.IFS(Tbl_DFR[[#This Row],[Filling Qty]]>=150,"HIGH",Tbl_DFR[[#This Row],[Filling Qty]]>=80,"medium",TRUE,"low")} -> low | V33: =IF(OR(Tbl_DFR[[#This Row],[CMP]]="HALDWANI",Tbl_DFR[[#This Row],[CMP]]="DEHRADUN"),"YES","NO") -> YES | W33: 45931 | Y33: 45931 | Z33: =IFERROR(TEXT(Tbl_DFR[[#This Row],[Date of filling]],"mmm"),"WIP") -> Oct | AA33: =IFERROR(YEAR(Tbl_DFR[[#This Row],[Date of filling]]),"WIP") -> 2025 | AB33: =IFERROR(TEXT(Tbl_DFR[[#This Row],[Date of filling]],"ddd"),"WIP") -> Wed | AD33: =_xlfn.XLOOKUP(Tbl_DFR[[#This Row],[SAP]],Site_master[SAP ID],Site_master[ [ TECHNICIAN Name] ],"Not found") -> Kapil Pal | AE33: =LEN(Tbl_DFR[[#This Row],[SAP]]) -> 18 | AF33: =IF(Tbl_DFR[[#This Row],[SAP LENGTH]]=18,"valid","check") -> valid
A34: 17 | B34: DEHRADUN | C34: =UPPER(TRIM(Tbl_DFR[[#This Row],[CMP]])) -> DEHRADUN | D34: Vivek Kumar | E34: UK17CA5176 | F34: ASHISH | G34: I-UW-JWGH-ENB-9001 | H34: 120301 | I34: 45933 | J34: 45933 | K34: =IF(OR(Tbl_DFR[[#This Row],[Date of filling]]="WIP",Tbl_DFR[[#This Row],[Date of Invoice ]]=""),"",Tbl_DFR[[#This Row],[Date of filling]]-Tbl_DFR[[#This Row],[Date of Invoice ]]) -> 0 | L34: =IF(ISNUMBER(Tbl_DFR[[#This Row],[Invoice filling gape]]),"valid","check") -> valid | M34: 7738 | N34: 1551 | O34: 20 | P34: 80 | Q34: =IF(Tbl_DFR[[#This Row],[Filling Qty]]>=150,"high","normal") -> normal | R34: =IF(AND(Tbl_DFR[[#This Row],[CMP]]="HALDWANI",Tbl_DFR[[#This Row],[Filling Qty]]>=150),"yes","no") -> no | S34: =IF(Tbl_DFR[[#This Row],[Filling Qty]]>=150,"high",IF(Tbl_DFR[[#This Row],[Filling Qty]]>=80,"medium","low")) -> medium | T34: =P34+O34 -> 100 | U34: {=_xlfn.IFS(Tbl_DFR[[#This Row],[Filling Qty]]>=150,"HIGH",Tbl_DFR[[#This Row],[Filling Qty]]>=80,"medium",TRUE,"low")} -> medium | V34: =IF(OR(Tbl_DFR[[#This Row],[CMP]]="HALDWANI",Tbl_DFR[[#This Row],[CMP]]="DEHRADUN"),"YES","NO") -> YES | W34: 45933 | X34: 45931 | Y34: 45931 | Z34: =IFERROR(TEXT(Tbl_DFR[[#This Row],[Date of filling]],"mmm"),"WIP") -> Oct | AA34: =IFERROR(YEAR(Tbl_DFR[[#This Row],[Date of filling]]),"WIP") -> 2025 | AB34: =IFERROR(TEXT(Tbl_DFR[[#This Row],[Date of filling]],"ddd"),"WIP") -> Fri | AD34: =_xlfn.XLOOKUP(Tbl_DFR[[#This Row],[SAP]],Site_master[SAP ID],Site_master[ [ TECHNICIAN Name] ],"Not found") -> Sandeep Kumar Saini | AE34: =LEN(Tbl_DFR[[#This Row],[SAP]]) -> 18 | AF34: =IF(Tbl_DFR[[#This Row],[SAP LENGTH]]=18,"valid","check") -> valid
A35: 17 | B35: HALDWANI | C35: =UPPER(TRIM(Tbl_DFR[[#This Row],[CMP]])) -> HALDWANI | D35: Aashish Rai | E35: UP21ET8573 | F35: AMAN | G35: I-UW-BZPR-ENB-9053 | H35: 80958 | I35: 45931 | J35: 45931 | K35: =IF(OR(Tbl_DFR[[#This Row],[Date of filling]]="WIP",Tbl_DFR[[#This Row],[Date of Invoice ]]=""),"",Tbl_DFR[[#This Row],[Date of filling]]-Tbl_DFR[[#This Row],[Date of Invoice ]]) -> 0 | L35: =IF(ISNUMBER(Tbl_DFR[[#This Row],[Invoice filling gape]]),"valid","check") -> valid | M35: 8560 | N35: 1593 | O35: 30 | P35: 40 | Q35: =IF(Tbl_DFR[[#This Row],[Filling Qty]]>=150,"high","normal") -> normal | R35: =IF(AND(Tbl_DFR[[#This Row],[CMP]]="HALDWANI",Tbl_DFR[[#This Row],[Filling Qty]]>=150),"yes","no") -> no | S35: =IF(Tbl_DFR[[#This Row],[Filling Qty]]>=150,"high",IF(Tbl_DFR[[#This Row],[Filling Qty]]>=80,"medium","low")) -> low | T35: =P35+O35 -> 70 | U35: {=_xlfn.IFS(Tbl_DFR[[#This Row],[Filling Qty]]>=150,"HIGH",Tbl_DFR[[#This Row],[Filling Qty]]>=80,"medium",TRUE,"low")} -> low | V35: =IF(OR(Tbl_DFR[[#This Row],[CMP]]="HALDWANI",Tbl_DFR[[#This Row],[CMP]]="DEHRADUN"),"YES","NO") -> YES | W35: 45931 | X35: 0.44513889 | Y35: 45931 | Z35: =IFERROR(TEXT(Tbl_DFR[[#This Row],[Date of filling]],"mmm"),"WIP") -> Oct | AA35: =IFERROR(YEAR(Tbl_DFR[[#This Row],[Date of filling]]),"WIP") -> 2025 | AB35: =IFERROR(TEXT(Tbl_DFR[[#This Row],[Date of filling]],"ddd"),"WIP") -> Wed | AC35: Ankit | AD35: =_xlfn.XLOOKUP(Tbl_DFR[[#This Row],[SAP]],Site_master[SAP ID],Site_master[ [ TECHNICIAN Name] ],"Not found") -> Kapil Pal | AE35: =LEN(Tbl_DFR[[#This Row],[SAP]]) -> 18 | AF35: =IF(Tbl_DFR[[#This Row],[SAP LENGTH]]=18,"valid","check") -> valid
A36: 18 | B36: DEHRADUN | C36: =UPPER(TRIM(Tbl_DFR[[#This Row],[CMP]])) -> DEHRADUN | D36: Vivek Kumar | E36: UK17CA5176 | F36: ASHISH | G36: I-UW-DRDN-ENB-0582 | H36: 120301 | I36: 45933 | J36: 45935 | K36: =IF(OR(Tbl_DFR[[#This Row],[Date of filling]]="WIP",Tbl_DFR[[#This Row],[Date of Invoice ]]=""),"",Tbl_DFR[[#This Row],[Date of filling]]-Tbl_DFR[[#This Row],[Date of Invoice ]]) -> 2 | L36: =IF(ISNUMBER(Tbl_DFR[[#This Row],[Invoice filling gape]]),"valid","check") -> valid | M36: 10331 | N36: 3468 | O36: 50 | P36: 80 | Q36: =IF(Tbl_DFR[[#This Row],[Filling Qty]]>=150,"high","normal") -> normal | R36: =IF(AND(Tbl_DFR[[#This Row],[CMP]]="HALDWANI",Tbl_DFR[[#This Row],[Filling Qty]]>=150),"yes","no") -> no | S36: =IF(Tbl_DFR[[#This Row],[Filling Qty]]>=150,"high",IF(Tbl_DFR[[#This Row],[Filling Qty]]>=80,"medium","low")) -> medium | T36: =P36+O36 -> 130 | U36: {=_xlfn.IFS(Tbl_DFR[[#This Row],[Filling Qty]]>=150,"HIGH",Tbl_DFR[[#This Row],[Filling Qty]]>=80,"medium",TRUE,"low")} -> medium | V36: =IF(OR(Tbl_DFR[[#This Row],[CMP]]="HALDWANI",Tbl_DFR[[#This Row],[CMP]]="DEHRADUN"),"YES","NO") -> YES | W36: 45933 | X36: 45931 | Y36: 45931 | Z36: =IFERROR(TEXT(Tbl_DFR[[#This Row],[Date of filling]],"mmm"),"WIP") -> Oct | AA36: =IFERROR(YEAR(Tbl_DFR[[#This Row],[Date of filling]]),"WIP") -> 2025 | AB36: =IFERROR(TEXT(Tbl_DFR[[#This Row],[Date of filling]],"ddd"),"WIP") -> Sun | AD36: =_xlfn.XLOOKUP(Tbl_DFR[[#This Row],[SAP]],Site_master[SAP ID],Site_master[ [ TECHNICIAN Name] ],"Not found") -> Amit Saini | AE36: =LEN(Tbl_DFR[[#This Row],[SAP]]) -> 18 | AF36: =IF(Tbl_DFR[[#This Row],[SAP LENGTH]]=18,"valid","check") -> valid
